[2023-12-03T19:10:40.580+0000] {taskinstance.py:1159} INFO - Dependencies all met for dep_context=non-requeueable deps ti=<TaskInstance: weather_scrapper.create_table scheduled__2023-11-29T00:00:00+00:00 [queued]>
[2023-12-03T19:10:40.616+0000] {taskinstance.py:1159} INFO - Dependencies all met for dep_context=requeueable deps ti=<TaskInstance: weather_scrapper.create_table scheduled__2023-11-29T00:00:00+00:00 [queued]>
[2023-12-03T19:10:40.620+0000] {taskinstance.py:1361} INFO - Starting attempt 1 of 1
[2023-12-03T19:10:40.676+0000] {taskinstance.py:1382} INFO - Executing <Task(PostgresOperator): create_table> on 2023-11-29 00:00:00+00:00
[2023-12-03T19:10:40.701+0000] {standard_task_runner.py:57} INFO - Started process 261 to run task
[2023-12-03T19:10:40.705+0000] {standard_task_runner.py:84} INFO - Running: ['***', 'tasks', 'run', 'weather_scrapper', 'create_table', 'scheduled__2023-11-29T00:00:00+00:00', '--job-id', '9', '--raw', '--subdir', 'DAGS_FOLDER/weather_scrapper.py', '--cfg-path', '/tmp/tmps3_vv9s7']
[2023-12-03T19:10:40.718+0000] {standard_task_runner.py:85} INFO - Job 9: Subtask create_table
[2023-12-03T19:10:40.927+0000] {task_command.py:416} INFO - Running <TaskInstance: weather_scrapper.create_table scheduled__2023-11-29T00:00:00+00:00 [running]> on host 046e595e6dd8
[2023-12-03T19:10:41.138+0000] {taskinstance.py:1662} INFO - Exporting env vars: AIRFLOW_CTX_DAG_OWNER='***' AIRFLOW_CTX_DAG_ID='weather_scrapper' AIRFLOW_CTX_TASK_ID='create_table' AIRFLOW_CTX_EXECUTION_DATE='2023-11-29T00:00:00+00:00' AIRFLOW_CTX_TRY_NUMBER='1' AIRFLOW_CTX_DAG_RUN_ID='scheduled__2023-11-29T00:00:00+00:00'
[2023-12-03T19:10:41.144+0000] {sql.py:274} INFO - Executing: 
        CREATE TABLE IF NOT EXISTS measures (
            city VARCHAR(255),
            timestamp TIMESTAMP,
            temperature FLOAT,
            humidity FLOAT,
            cloudiness FLOAT,
            wind_speed FLOAT
        );
        
[2023-12-03T19:10:41.193+0000] {taskinstance.py:1937} ERROR - Task failed with exception
Traceback (most recent call last):
  File "/home/airflow/.local/lib/python3.8/site-packages/airflow/providers/common/sql/operators/sql.py", line 275, in execute
    hook = self.get_db_hook()
  File "/home/airflow/.local/lib/python3.8/site-packages/airflow/providers/common/sql/operators/sql.py", line 186, in get_db_hook
    return self._hook
  File "/usr/local/lib/python3.8/functools.py", line 967, in __get__
    val = self.func(instance)
  File "/home/airflow/.local/lib/python3.8/site-packages/airflow/providers/common/sql/operators/sql.py", line 148, in _hook
    conn = BaseHook.get_connection(conn_id)
  File "/home/airflow/.local/lib/python3.8/site-packages/airflow/hooks/base.py", line 72, in get_connection
    conn = Connection.get_connection_from_secrets(conn_id)
  File "/home/airflow/.local/lib/python3.8/site-packages/airflow/models/connection.py", line 477, in get_connection_from_secrets
    raise AirflowNotFoundException(f"The conn_id `{conn_id}` isn't defined")
airflow.exceptions.AirflowNotFoundException: The conn_id `hw1_postgres` isn't defined
[2023-12-03T19:10:41.221+0000] {taskinstance.py:1400} INFO - Marking task as FAILED. dag_id=weather_scrapper, task_id=create_table, execution_date=20231129T000000, start_date=20231203T191040, end_date=20231203T191041
[2023-12-03T19:10:41.296+0000] {standard_task_runner.py:104} ERROR - Failed to execute job 9 for task create_table (The conn_id `hw1_postgres` isn't defined; 261)
[2023-12-03T19:10:41.358+0000] {local_task_job_runner.py:228} INFO - Task exited with return code 1
[2023-12-03T19:10:41.456+0000] {taskinstance.py:2778} INFO - 0 downstream tasks scheduled from follow-on schedule check
