[2023-12-03T19:10:39.907+0000] {taskinstance.py:1159} INFO - Dependencies all met for dep_context=non-requeueable deps ti=<TaskInstance: weather_scrapper.create_table manual__2023-12-03T19:10:32.771805+00:00 [queued]>
[2023-12-03T19:10:39.974+0000] {taskinstance.py:1159} INFO - Dependencies all met for dep_context=requeueable deps ti=<TaskInstance: weather_scrapper.create_table manual__2023-12-03T19:10:32.771805+00:00 [queued]>
[2023-12-03T19:10:39.993+0000] {taskinstance.py:1361} INFO - Starting attempt 1 of 1
[2023-12-03T19:10:40.128+0000] {taskinstance.py:1382} INFO - Executing <Task(PostgresOperator): create_table> on 2023-12-03 19:10:32.771805+00:00
[2023-12-03T19:10:40.147+0000] {standard_task_runner.py:57} INFO - Started process 257 to run task
[2023-12-03T19:10:40.154+0000] {standard_task_runner.py:84} INFO - Running: ['***', 'tasks', 'run', 'weather_scrapper', 'create_table', 'manual__2023-12-03T19:10:32.771805+00:00', '--job-id', '5', '--raw', '--subdir', 'DAGS_FOLDER/weather_scrapper.py', '--cfg-path', '/tmp/tmpdu6q7nl_']
[2023-12-03T19:10:40.207+0000] {standard_task_runner.py:85} INFO - Job 5: Subtask create_table
[2023-12-03T19:10:40.452+0000] {task_command.py:416} INFO - Running <TaskInstance: weather_scrapper.create_table manual__2023-12-03T19:10:32.771805+00:00 [running]> on host 046e595e6dd8
[2023-12-03T19:10:40.671+0000] {taskinstance.py:1662} INFO - Exporting env vars: AIRFLOW_CTX_DAG_OWNER='***' AIRFLOW_CTX_DAG_ID='weather_scrapper' AIRFLOW_CTX_TASK_ID='create_table' AIRFLOW_CTX_EXECUTION_DATE='2023-12-03T19:10:32.771805+00:00' AIRFLOW_CTX_TRY_NUMBER='1' AIRFLOW_CTX_DAG_RUN_ID='manual__2023-12-03T19:10:32.771805+00:00'
[2023-12-03T19:10:40.675+0000] {sql.py:274} INFO - Executing: 
        CREATE TABLE IF NOT EXISTS measures (
            city VARCHAR(255),
            timestamp TIMESTAMP,
            temperature FLOAT,
            humidity FLOAT,
            cloudiness FLOAT,
            wind_speed FLOAT
        );
        
[2023-12-03T19:10:40.731+0000] {taskinstance.py:1937} ERROR - Task failed with exception
Traceback (most recent call last):
  File "/home/airflow/.local/lib/python3.8/site-packages/airflow/providers/common/sql/operators/sql.py", line 275, in execute
    hook = self.get_db_hook()
  File "/home/airflow/.local/lib/python3.8/site-packages/airflow/providers/common/sql/operators/sql.py", line 186, in get_db_hook
    return self._hook
  File "/usr/local/lib/python3.8/functools.py", line 967, in __get__
    val = self.func(instance)
  File "/home/airflow/.local/lib/python3.8/site-packages/airflow/providers/common/sql/operators/sql.py", line 148, in _hook
    conn = BaseHook.get_connection(conn_id)
  File "/home/airflow/.local/lib/python3.8/site-packages/airflow/hooks/base.py", line 72, in get_connection
    conn = Connection.get_connection_from_secrets(conn_id)
  File "/home/airflow/.local/lib/python3.8/site-packages/airflow/models/connection.py", line 477, in get_connection_from_secrets
    raise AirflowNotFoundException(f"The conn_id `{conn_id}` isn't defined")
airflow.exceptions.AirflowNotFoundException: The conn_id `hw1_postgres` isn't defined
[2023-12-03T19:10:40.759+0000] {taskinstance.py:1400} INFO - Marking task as FAILED. dag_id=weather_scrapper, task_id=create_table, execution_date=20231203T191032, start_date=20231203T191039, end_date=20231203T191040
[2023-12-03T19:10:40.803+0000] {standard_task_runner.py:104} ERROR - Failed to execute job 5 for task create_table (The conn_id `hw1_postgres` isn't defined; 257)
[2023-12-03T19:10:40.871+0000] {local_task_job_runner.py:228} INFO - Task exited with return code 1
[2023-12-03T19:10:41.189+0000] {taskinstance.py:2778} INFO - 0 downstream tasks scheduled from follow-on schedule check
