[2023-12-03T19:25:57.202+0000] {taskinstance.py:1159} INFO - Dependencies all met for dep_context=non-requeueable deps ti=<TaskInstance: weather_scrapper.create_table manual__2023-12-03T19:25:55.117362+00:00 [queued]>
[2023-12-03T19:25:57.210+0000] {taskinstance.py:1159} INFO - Dependencies all met for dep_context=requeueable deps ti=<TaskInstance: weather_scrapper.create_table manual__2023-12-03T19:25:55.117362+00:00 [queued]>
[2023-12-03T19:25:57.211+0000] {taskinstance.py:1361} INFO - Starting attempt 1 of 1
[2023-12-03T19:25:57.227+0000] {taskinstance.py:1382} INFO - Executing <Task(PostgresOperator): create_table> on 2023-12-03 19:25:55.117362+00:00
[2023-12-03T19:25:57.232+0000] {standard_task_runner.py:57} INFO - Started process 518 to run task
[2023-12-03T19:25:57.236+0000] {standard_task_runner.py:84} INFO - Running: ['***', 'tasks', 'run', 'weather_scrapper', 'create_table', 'manual__2023-12-03T19:25:55.117362+00:00', '--job-id', '19', '--raw', '--subdir', 'DAGS_FOLDER/weather_scrapper.py', '--cfg-path', '/tmp/tmp0wd238os']
[2023-12-03T19:25:57.240+0000] {standard_task_runner.py:85} INFO - Job 19: Subtask create_table
[2023-12-03T19:25:57.300+0000] {task_command.py:416} INFO - Running <TaskInstance: weather_scrapper.create_table manual__2023-12-03T19:25:55.117362+00:00 [running]> on host 046e595e6dd8
[2023-12-03T19:25:57.377+0000] {taskinstance.py:1662} INFO - Exporting env vars: AIRFLOW_CTX_DAG_OWNER='***' AIRFLOW_CTX_DAG_ID='weather_scrapper' AIRFLOW_CTX_TASK_ID='create_table' AIRFLOW_CTX_EXECUTION_DATE='2023-12-03T19:25:55.117362+00:00' AIRFLOW_CTX_TRY_NUMBER='1' AIRFLOW_CTX_DAG_RUN_ID='manual__2023-12-03T19:25:55.117362+00:00'
[2023-12-03T19:25:57.381+0000] {sql.py:274} INFO - Executing: 
        CREATE TABLE IF NOT EXISTS measures (
            city VARCHAR(255),
            timestamp TIMESTAMP,
            temperature FLOAT,
            humidity FLOAT,
            cloudiness FLOAT,
            wind_speed FLOAT
        );
        
[2023-12-03T19:25:57.393+0000] {base.py:73} INFO - Using connection ID 'hw1_postgres' for task execution.
[2023-12-03T19:25:57.405+0000] {base.py:73} INFO - Using connection ID 'hw1_postgres' for task execution.
[2023-12-03T19:25:57.407+0000] {taskinstance.py:1937} ERROR - Task failed with exception
Traceback (most recent call last):
  File "/home/airflow/.local/lib/python3.8/site-packages/airflow/providers/common/sql/operators/sql.py", line 280, in execute
    output = hook.run(
  File "/home/airflow/.local/lib/python3.8/site-packages/airflow/providers/common/sql/hooks/sql.py", line 385, in run
    with closing(self.get_conn()) as conn:
  File "/home/airflow/.local/lib/python3.8/site-packages/airflow/providers/postgres/hooks/postgres.py", line 155, in get_conn
    self.conn = psycopg2.connect(**conn_args)
  File "/home/airflow/.local/lib/python3.8/site-packages/psycopg2/__init__.py", line 122, in connect
    conn = _connect(dsn, connection_factory=connection_factory, **kwasync)
psycopg2.OperationalError: connection to server on socket "/var/run/postgresql/.s.PGSQL.5432" failed: No such file or directory
	Is the server running locally and accepting connections on that socket?

[2023-12-03T19:25:57.418+0000] {taskinstance.py:1400} INFO - Marking task as FAILED. dag_id=weather_scrapper, task_id=create_table, execution_date=20231203T192555, start_date=20231203T192557, end_date=20231203T192557
[2023-12-03T19:25:57.437+0000] {standard_task_runner.py:104} ERROR - Failed to execute job 19 for task create_table (connection to server on socket "/var/run/postgresql/.s.PGSQL.5432" failed: No such file or directory
	Is the server running locally and accepting connections on that socket?
; 518)
[2023-12-03T19:25:57.448+0000] {local_task_job_runner.py:228} INFO - Task exited with return code 1
[2023-12-03T19:25:57.488+0000] {taskinstance.py:2778} INFO - 0 downstream tasks scheduled from follow-on schedule check
